{
    "type": "bundle",
    "id": "bundle--ec00ea84-dc42-4747-90f0-9415ead8e880",
    "objects": [
        {
            "type": "vulnerability",
            "spec_version": "2.1",
            "id": "vulnerability--36872ee2-c6e3-483f-88b6-83c9fce2b79a",
            "created_by_ref": "identity--8ce3f695-d5a4-4dc8-9e93-a65af453a31a",
            "created": "2023-07-07T00:05:46.52701Z",
            "modified": "2023-07-07T00:05:46.52701Z",
            "name": "CVE-2023-29824",
            "description": "A use-after-free issue was discovered in Py_FindObjects() function in SciPy versions prior to 1.8.0.",
            "external_references": [
                {
                    "source_name": "cve",
                    "external_id": "CVE-2023-29824"
                }
            ]
        }
    ]
}